2022-06-07 11:37:34,708 ERROR: Exception on /reset_password_request [POST] [in /home/denis/Dev/checkiner/.venv/lib/python3.8/site-packages/flask/app.py:1455]
Traceback (most recent call last):
  File "/home/denis/Dev/checkiner/.venv/lib/python3.8/site-packages/flask/app.py", line 2077, in wsgi_app
    response = self.full_dispatch_request()
  File "/home/denis/Dev/checkiner/.venv/lib/python3.8/site-packages/flask/app.py", line 1525, in full_dispatch_request
    rv = self.handle_user_exception(e)
  File "/home/denis/Dev/checkiner/.venv/lib/python3.8/site-packages/flask/app.py", line 1523, in full_dispatch_request
    rv = self.dispatch_request()
  File "/home/denis/Dev/checkiner/.venv/lib/python3.8/site-packages/flask/app.py", line 1509, in dispatch_request
    return self.ensure_sync(self.view_functions[rule.endpoint])(**req.view_args)
  File "/home/denis/Dev/checkiner/app/routes.py", line 169, in reset_password_request
    send_password_reset_email(user)
  File "/home/denis/Dev/checkiner/app/email.py", line 21, in send_password_reset_email
    html_body=render_template('reset_password_request.html',
  File "/home/denis/Dev/checkiner/.venv/lib/python3.8/site-packages/flask/templating.py", line 148, in render_template
    return _render(
  File "/home/denis/Dev/checkiner/.venv/lib/python3.8/site-packages/flask/templating.py", line 128, in _render
    rv = template.render(context)
  File "/home/denis/Dev/checkiner/.venv/lib/python3.8/site-packages/jinja2/environment.py", line 1291, in render
    self.environment.handle_exception()
  File "/home/denis/Dev/checkiner/.venv/lib/python3.8/site-packages/jinja2/environment.py", line 926, in handle_exception
    raise rewrite_traceback_stack(source=source)
  File "/home/denis/Dev/checkiner/app/templates/reset_password_request.html", line 1, in top-level template code
    {% extends "base.html" %}
  File "/home/denis/Dev/checkiner/app/templates/base.html", line 26, in top-level template code
    {% block content %}
  File "/home/denis/Dev/checkiner/app/templates/reset_password_request.html", line 6, in block 'content'
    {{ form.hidden_tag() }}
  File "/home/denis/Dev/checkiner/.venv/lib/python3.8/site-packages/jinja2/environment.py", line 475, in getattr
    return getattr(obj, attribute)
jinja2.exceptions.UndefinedError: 'form' is undefined
2022-06-07 11:39:44,955 ERROR: Exception on /reset_password_request [POST] [in /home/denis/Dev/checkiner/.venv/lib/python3.8/site-packages/flask/app.py:1455]
Traceback (most recent call last):
  File "/home/denis/Dev/checkiner/.venv/lib/python3.8/site-packages/flask/app.py", line 2077, in wsgi_app
    response = self.full_dispatch_request()
  File "/home/denis/Dev/checkiner/.venv/lib/python3.8/site-packages/flask/app.py", line 1525, in full_dispatch_request
    rv = self.handle_user_exception(e)
  File "/home/denis/Dev/checkiner/.venv/lib/python3.8/site-packages/flask/app.py", line 1523, in full_dispatch_request
    rv = self.dispatch_request()
  File "/home/denis/Dev/checkiner/.venv/lib/python3.8/site-packages/flask/app.py", line 1509, in dispatch_request
    return self.ensure_sync(self.view_functions[rule.endpoint])(**req.view_args)
  File "/home/denis/Dev/checkiner/app/routes.py", line 170, in reset_password_request
    send_password_reset_email(user)
  File "/home/denis/Dev/checkiner/app/email.py", line 21, in send_password_reset_email
    html_body=render_template('reset_password_request.html',
  File "/home/denis/Dev/checkiner/.venv/lib/python3.8/site-packages/flask/templating.py", line 148, in render_template
    return _render(
  File "/home/denis/Dev/checkiner/.venv/lib/python3.8/site-packages/flask/templating.py", line 128, in _render
    rv = template.render(context)
  File "/home/denis/Dev/checkiner/.venv/lib/python3.8/site-packages/jinja2/environment.py", line 1291, in render
    self.environment.handle_exception()
  File "/home/denis/Dev/checkiner/.venv/lib/python3.8/site-packages/jinja2/environment.py", line 926, in handle_exception
    raise rewrite_traceback_stack(source=source)
  File "/home/denis/Dev/checkiner/app/templates/reset_password_request.html", line 1, in top-level template code
    {% extends "base.html" %}
  File "/home/denis/Dev/checkiner/app/templates/base.html", line 26, in top-level template code
    {% block content %}
  File "/home/denis/Dev/checkiner/app/templates/reset_password_request.html", line 6, in block 'content'
    {{ form.hidden_tag() }}
  File "/home/denis/Dev/checkiner/.venv/lib/python3.8/site-packages/jinja2/environment.py", line 475, in getattr
    return getattr(obj, attribute)
jinja2.exceptions.UndefinedError: 'form' is undefined
2022-06-07 11:42:19,904 ERROR: Exception on /reset_password_request [POST] [in /home/denis/Dev/checkiner/.venv/lib/python3.8/site-packages/flask/app.py:1455]
Traceback (most recent call last):
  File "/home/denis/Dev/checkiner/.venv/lib/python3.8/site-packages/flask/app.py", line 2077, in wsgi_app
    response = self.full_dispatch_request()
  File "/home/denis/Dev/checkiner/.venv/lib/python3.8/site-packages/flask/app.py", line 1525, in full_dispatch_request
    rv = self.handle_user_exception(e)
  File "/home/denis/Dev/checkiner/.venv/lib/python3.8/site-packages/flask/app.py", line 1523, in full_dispatch_request
    rv = self.dispatch_request()
  File "/home/denis/Dev/checkiner/.venv/lib/python3.8/site-packages/flask/app.py", line 1509, in dispatch_request
    return self.ensure_sync(self.view_functions[rule.endpoint])(**req.view_args)
  File "/home/denis/Dev/checkiner/app/routes.py", line 169, in reset_password_request
    send_password_reset_email(user)
  File "/home/denis/Dev/checkiner/app/email.py", line 21, in send_password_reset_email
    html_body=render_template('reset_password.html',
  File "/home/denis/Dev/checkiner/.venv/lib/python3.8/site-packages/flask/templating.py", line 148, in render_template
    return _render(
  File "/home/denis/Dev/checkiner/.venv/lib/python3.8/site-packages/flask/templating.py", line 128, in _render
    rv = template.render(context)
  File "/home/denis/Dev/checkiner/.venv/lib/python3.8/site-packages/jinja2/environment.py", line 1291, in render
    self.environment.handle_exception()
  File "/home/denis/Dev/checkiner/.venv/lib/python3.8/site-packages/jinja2/environment.py", line 926, in handle_exception
    raise rewrite_traceback_stack(source=source)
  File "/home/denis/Dev/checkiner/app/templates/reset_password.html", line 1, in top-level template code
    {% extends "base.html" %}
  File "/home/denis/Dev/checkiner/app/templates/base.html", line 26, in top-level template code
    {% block content %}
  File "/home/denis/Dev/checkiner/app/templates/reset_password.html", line 6, in block 'content'
    {{ form.hidden_tag() }}
  File "/home/denis/Dev/checkiner/.venv/lib/python3.8/site-packages/jinja2/environment.py", line 475, in getattr
    return getattr(obj, attribute)
jinja2.exceptions.UndefinedError: 'form' is undefined
2022-06-07 11:49:54,474 ERROR: Exception on /index [GET] [in /home/denis/Dev/checkiner/.venv/lib/python3.8/site-packages/flask/app.py:1455]
Traceback (most recent call last):
  File "/home/denis/Dev/checkiner/.venv/lib/python3.8/site-packages/flask/app.py", line 2077, in wsgi_app
    response = self.full_dispatch_request()
  File "/home/denis/Dev/checkiner/.venv/lib/python3.8/site-packages/flask/app.py", line 1525, in full_dispatch_request
    rv = self.handle_user_exception(e)
  File "/home/denis/Dev/checkiner/.venv/lib/python3.8/site-packages/flask/app.py", line 1523, in full_dispatch_request
    rv = self.dispatch_request()
  File "/home/denis/Dev/checkiner/.venv/lib/python3.8/site-packages/flask/app.py", line 1509, in dispatch_request
    return self.ensure_sync(self.view_functions[rule.endpoint])(**req.view_args)
  File "/home/denis/Dev/checkiner/app/routes.py", line 25, in index
    posts = current_user.followed_posts().paginate(
AttributeError: 'AnonymousUserMixin' object has no attribute 'followed_posts'
2022-06-07 11:53:29,133 ERROR: Exception on /index [GET] [in /home/denis/Dev/checkiner/.venv/lib/python3.8/site-packages/flask/app.py:1455]
Traceback (most recent call last):
  File "/home/denis/Dev/checkiner/.venv/lib/python3.8/site-packages/flask/app.py", line 2077, in wsgi_app
    response = self.full_dispatch_request()
  File "/home/denis/Dev/checkiner/.venv/lib/python3.8/site-packages/flask/app.py", line 1525, in full_dispatch_request
    rv = self.handle_user_exception(e)
  File "/home/denis/Dev/checkiner/.venv/lib/python3.8/site-packages/flask/app.py", line 1523, in full_dispatch_request
    rv = self.dispatch_request()
  File "/home/denis/Dev/checkiner/.venv/lib/python3.8/site-packages/flask/app.py", line 1509, in dispatch_request
    return self.ensure_sync(self.view_functions[rule.endpoint])(**req.view_args)
  File "/home/denis/Dev/checkiner/app/routes.py", line 26, in index
    posts = current_user.followed_posts().paginate(
AttributeError: 'AnonymousUserMixin' object has no attribute 'followed_posts'
2022-06-07 11:54:05,937 ERROR: Exception on /index [GET] [in /home/denis/Dev/checkiner/.venv/lib/python3.8/site-packages/flask/app.py:1455]
Traceback (most recent call last):
  File "/home/denis/Dev/checkiner/.venv/lib/python3.8/site-packages/flask/app.py", line 2077, in wsgi_app
    response = self.full_dispatch_request()
  File "/home/denis/Dev/checkiner/.venv/lib/python3.8/site-packages/flask/app.py", line 1525, in full_dispatch_request
    rv = self.handle_user_exception(e)
  File "/home/denis/Dev/checkiner/.venv/lib/python3.8/site-packages/flask/app.py", line 1523, in full_dispatch_request
    rv = self.dispatch_request()
  File "/home/denis/Dev/checkiner/.venv/lib/python3.8/site-packages/flask/app.py", line 1509, in dispatch_request
    return self.ensure_sync(self.view_functions[rule.endpoint])(**req.view_args)
  File "/home/denis/Dev/checkiner/app/routes.py", line 27, in index
    posts = current_user.followed_posts().paginate(
AttributeError: 'AnonymousUserMixin' object has no attribute 'followed_posts'
