2022-06-06 17:30:19,462 ERROR: Exception on /explore [GET] [in /home/denis/Dev/checkiner/.venv/lib/python3.8/site-packages/flask/app.py:1455]
Traceback (most recent call last):
  File "/home/denis/Dev/checkiner/.venv/lib/python3.8/site-packages/flask/app.py", line 2077, in wsgi_app
    response = self.full_dispatch_request()
  File "/home/denis/Dev/checkiner/.venv/lib/python3.8/site-packages/flask/app.py", line 1525, in full_dispatch_request
    rv = self.handle_user_exception(e)
  File "/home/denis/Dev/checkiner/.venv/lib/python3.8/site-packages/flask/app.py", line 1523, in full_dispatch_request
    rv = self.dispatch_request()
  File "/home/denis/Dev/checkiner/.venv/lib/python3.8/site-packages/flask/app.py", line 1509, in dispatch_request
    return self.ensure_sync(self.view_functions[rule.endpoint])(**req.view_args)
  File "/home/denis/Dev/checkiner/.venv/lib/python3.8/site-packages/flask_login/utils.py", line 303, in decorated_view
    return current_app.ensure_sync(func)(*args, **kwargs)
  File "/home/denis/Dev/checkiner/app/routes.py", line 136, in explore
    return render_template('index.html', title='Explore', posts=posts)
  File "/home/denis/Dev/checkiner/.venv/lib/python3.8/site-packages/flask/templating.py", line 148, in render_template
    return _render(
  File "/home/denis/Dev/checkiner/.venv/lib/python3.8/site-packages/flask/templating.py", line 128, in _render
    rv = template.render(context)
  File "/home/denis/Dev/checkiner/.venv/lib/python3.8/site-packages/jinja2/environment.py", line 1291, in render
    self.environment.handle_exception()
  File "/home/denis/Dev/checkiner/.venv/lib/python3.8/site-packages/jinja2/environment.py", line 926, in handle_exception
    raise rewrite_traceback_stack(source=source)
  File "/home/denis/Dev/checkiner/app/templates/index.html", line 1, in top-level template code
    {% extends "base.html" %}
  File "/home/denis/Dev/checkiner/app/templates/base.html", line 26, in top-level template code
    {% block content %}
  File "/home/denis/Dev/checkiner/app/templates/index.html", line 23, in block 'content'
    {% include '_post_item.html' %}
  File "/home/denis/Dev/checkiner/.venv/lib/python3.8/site-packages/flask/templating.py", line 59, in get_source
    return self._get_source_fast(environment, template)
  File "/home/denis/Dev/checkiner/.venv/lib/python3.8/site-packages/flask/templating.py", line 95, in _get_source_fast
    raise TemplateNotFound(template)
jinja2.exceptions.TemplateNotFound: _post_item.html
2022-06-06 17:30:21,036 ERROR: Exception on /index [GET] [in /home/denis/Dev/checkiner/.venv/lib/python3.8/site-packages/flask/app.py:1455]
Traceback (most recent call last):
  File "/home/denis/Dev/checkiner/.venv/lib/python3.8/site-packages/flask/app.py", line 2077, in wsgi_app
    response = self.full_dispatch_request()
  File "/home/denis/Dev/checkiner/.venv/lib/python3.8/site-packages/flask/app.py", line 1525, in full_dispatch_request
    rv = self.handle_user_exception(e)
  File "/home/denis/Dev/checkiner/.venv/lib/python3.8/site-packages/flask/app.py", line 1523, in full_dispatch_request
    rv = self.dispatch_request()
  File "/home/denis/Dev/checkiner/.venv/lib/python3.8/site-packages/flask/app.py", line 1509, in dispatch_request
    return self.ensure_sync(self.view_functions[rule.endpoint])(**req.view_args)
  File "/home/denis/Dev/checkiner/app/routes.py", line 22, in index
    return render_template("index.html", title='Index', form=form,
  File "/home/denis/Dev/checkiner/.venv/lib/python3.8/site-packages/flask/templating.py", line 148, in render_template
    return _render(
  File "/home/denis/Dev/checkiner/.venv/lib/python3.8/site-packages/flask/templating.py", line 128, in _render
    rv = template.render(context)
  File "/home/denis/Dev/checkiner/.venv/lib/python3.8/site-packages/jinja2/environment.py", line 1291, in render
    self.environment.handle_exception()
  File "/home/denis/Dev/checkiner/.venv/lib/python3.8/site-packages/jinja2/environment.py", line 926, in handle_exception
    raise rewrite_traceback_stack(source=source)
  File "/home/denis/Dev/checkiner/app/templates/index.html", line 1, in top-level template code
    {% extends "base.html" %}
  File "/home/denis/Dev/checkiner/app/templates/base.html", line 26, in top-level template code
    {% block content %}
  File "/home/denis/Dev/checkiner/app/templates/index.html", line 23, in block 'content'
    {% include '_post_item.html' %}
  File "/home/denis/Dev/checkiner/.venv/lib/python3.8/site-packages/flask/templating.py", line 59, in get_source
    return self._get_source_fast(environment, template)
  File "/home/denis/Dev/checkiner/.venv/lib/python3.8/site-packages/flask/templating.py", line 95, in _get_source_fast
    raise TemplateNotFound(template)
jinja2.exceptions.TemplateNotFound: _post_item.html
2022-06-06 17:30:22,331 ERROR: Exception on /explore [GET] [in /home/denis/Dev/checkiner/.venv/lib/python3.8/site-packages/flask/app.py:1455]
Traceback (most recent call last):
  File "/home/denis/Dev/checkiner/.venv/lib/python3.8/site-packages/flask/app.py", line 2077, in wsgi_app
    response = self.full_dispatch_request()
  File "/home/denis/Dev/checkiner/.venv/lib/python3.8/site-packages/flask/app.py", line 1525, in full_dispatch_request
    rv = self.handle_user_exception(e)
  File "/home/denis/Dev/checkiner/.venv/lib/python3.8/site-packages/flask/app.py", line 1523, in full_dispatch_request
    rv = self.dispatch_request()
  File "/home/denis/Dev/checkiner/.venv/lib/python3.8/site-packages/flask/app.py", line 1509, in dispatch_request
    return self.ensure_sync(self.view_functions[rule.endpoint])(**req.view_args)
  File "/home/denis/Dev/checkiner/.venv/lib/python3.8/site-packages/flask_login/utils.py", line 303, in decorated_view
    return current_app.ensure_sync(func)(*args, **kwargs)
  File "/home/denis/Dev/checkiner/app/routes.py", line 136, in explore
    return render_template('index.html', title='Explore', posts=posts)
  File "/home/denis/Dev/checkiner/.venv/lib/python3.8/site-packages/flask/templating.py", line 148, in render_template
    return _render(
  File "/home/denis/Dev/checkiner/.venv/lib/python3.8/site-packages/flask/templating.py", line 128, in _render
    rv = template.render(context)
  File "/home/denis/Dev/checkiner/.venv/lib/python3.8/site-packages/jinja2/environment.py", line 1291, in render
    self.environment.handle_exception()
  File "/home/denis/Dev/checkiner/.venv/lib/python3.8/site-packages/jinja2/environment.py", line 926, in handle_exception
    raise rewrite_traceback_stack(source=source)
  File "/home/denis/Dev/checkiner/app/templates/index.html", line 1, in top-level template code
    {% extends "base.html" %}
  File "/home/denis/Dev/checkiner/app/templates/base.html", line 26, in top-level template code
    {% block content %}
  File "/home/denis/Dev/checkiner/app/templates/index.html", line 23, in block 'content'
    {% include '_post_item.html' %}
  File "/home/denis/Dev/checkiner/.venv/lib/python3.8/site-packages/flask/templating.py", line 59, in get_source
    return self._get_source_fast(environment, template)
  File "/home/denis/Dev/checkiner/.venv/lib/python3.8/site-packages/flask/templating.py", line 95, in _get_source_fast
    raise TemplateNotFound(template)
jinja2.exceptions.TemplateNotFound: _post_item.html
2022-06-06 17:30:31,683 INFO: Checkiner startup [in /home/denis/Dev/checkiner/app/__init__.py:46]
2022-06-07 09:09:43,021 INFO: Checkiner startup [in /home/denis/Dev/checkiner/app/__init__.py:46]
2022-06-07 09:30:15,549 INFO: Checkiner startup [in /home/denis/Dev/checkiner/app/__init__.py:46]
2022-06-07 11:11:23,549 INFO: Checkiner startup [in /home/denis/Dev/checkiner/app/__init__.py:49]
2022-06-07 11:11:35,084 ERROR: Exception on /index [GET] [in /home/denis/Dev/checkiner/.venv/lib/python3.8/site-packages/flask/app.py:1455]
Traceback (most recent call last):
  File "/home/denis/Dev/checkiner/.venv/lib/python3.8/site-packages/flask/app.py", line 2077, in wsgi_app
    response = self.full_dispatch_request()
  File "/home/denis/Dev/checkiner/.venv/lib/python3.8/site-packages/flask/app.py", line 1525, in full_dispatch_request
    rv = self.handle_user_exception(e)
  File "/home/denis/Dev/checkiner/.venv/lib/python3.8/site-packages/flask/app.py", line 1523, in full_dispatch_request
    rv = self.dispatch_request()
  File "/home/denis/Dev/checkiner/.venv/lib/python3.8/site-packages/flask/app.py", line 1509, in dispatch_request
    return self.ensure_sync(self.view_functions[rule.endpoint])(**req.view_args)
  File "/home/denis/Dev/checkiner/app/routes.py", line 25, in index
    posts = current_user.followed_posts().paginate(
AttributeError: 'AnonymousUserMixin' object has no attribute 'followed_posts'
2022-06-07 11:12:00,280 ERROR: Exception on /reset_password_request [POST] [in /home/denis/Dev/checkiner/.venv/lib/python3.8/site-packages/flask/app.py:1455]
Traceback (most recent call last):
  File "/home/denis/Dev/checkiner/.venv/lib/python3.8/site-packages/flask/app.py", line 2077, in wsgi_app
    response = self.full_dispatch_request()
  File "/home/denis/Dev/checkiner/.venv/lib/python3.8/site-packages/flask/app.py", line 1525, in full_dispatch_request
    rv = self.handle_user_exception(e)
  File "/home/denis/Dev/checkiner/.venv/lib/python3.8/site-packages/flask/app.py", line 1523, in full_dispatch_request
    rv = self.dispatch_request()
  File "/home/denis/Dev/checkiner/.venv/lib/python3.8/site-packages/flask/app.py", line 1509, in dispatch_request
    return self.ensure_sync(self.view_functions[rule.endpoint])(**req.view_args)
  File "/home/denis/Dev/checkiner/app/routes.py", line 168, in reset_password_request
    send_password_reset_email(user)
  File "/home/denis/Dev/checkiner/app/email.py", line 15, in send_password_reset_email
    token = user.get_reset_password_token()
  File "/home/denis/Dev/checkiner/app/models.py", line 65, in get_reset_password_token
    return jwt.encode(
AttributeError: 'str' object has no attribute 'decode'
2022-06-07 11:15:39,511 INFO: Checkiner startup [in /home/denis/Dev/checkiner/app/__init__.py:49]
