2022-06-07 11:15:46,723 ERROR: Exception on /reset_password_request [POST] [in /home/denis/Dev/checkiner/.venv/lib/python3.8/site-packages/flask/app.py:1455]
Traceback (most recent call last):
  File "/home/denis/Dev/checkiner/.venv/lib/python3.8/site-packages/flask/app.py", line 2077, in wsgi_app
    response = self.full_dispatch_request()
  File "/home/denis/Dev/checkiner/.venv/lib/python3.8/site-packages/flask/app.py", line 1525, in full_dispatch_request
    rv = self.handle_user_exception(e)
  File "/home/denis/Dev/checkiner/.venv/lib/python3.8/site-packages/flask/app.py", line 1523, in full_dispatch_request
    rv = self.dispatch_request()
  File "/home/denis/Dev/checkiner/.venv/lib/python3.8/site-packages/flask/app.py", line 1509, in dispatch_request
    return self.ensure_sync(self.view_functions[rule.endpoint])(**req.view_args)
  File "/home/denis/Dev/checkiner/app/routes.py", line 168, in reset_password_request
    send_password_reset_email(user)
  File "/home/denis/Dev/checkiner/app/email.py", line 15, in send_password_reset_email
    token = user.get_reset_password_token()
  File "/home/denis/Dev/checkiner/app/models.py", line 66, in get_reset_password_token
    return jwt.encode(
AttributeError: 'str' object has no attribute 'decode'
2022-06-07 11:17:23,696 INFO: Checkiner startup [in /home/denis/Dev/checkiner/app/__init__.py:49]
2022-06-07 11:17:36,013 ERROR: Exception on /reset_password_request [POST] [in /home/denis/Dev/checkiner/.venv/lib/python3.8/site-packages/flask/app.py:1455]
Traceback (most recent call last):
  File "/home/denis/Dev/checkiner/.venv/lib/python3.8/site-packages/flask/app.py", line 2077, in wsgi_app
    response = self.full_dispatch_request()
  File "/home/denis/Dev/checkiner/.venv/lib/python3.8/site-packages/flask/app.py", line 1525, in full_dispatch_request
    rv = self.handle_user_exception(e)
  File "/home/denis/Dev/checkiner/.venv/lib/python3.8/site-packages/flask/app.py", line 1523, in full_dispatch_request
    rv = self.dispatch_request()
  File "/home/denis/Dev/checkiner/.venv/lib/python3.8/site-packages/flask/app.py", line 1509, in dispatch_request
    return self.ensure_sync(self.view_functions[rule.endpoint])(**req.view_args)
  File "/home/denis/Dev/checkiner/app/routes.py", line 168, in reset_password_request
    send_password_reset_email(user)
  File "/home/denis/Dev/checkiner/app/email.py", line 15, in send_password_reset_email
    token = user.get_reset_password_token()
  File "/home/denis/Dev/checkiner/app/models.py", line 66, in get_reset_password_token
    return jwt.encode(
AttributeError: 'str' object has no attribute 'decode'
2022-06-07 11:19:29,608 INFO: Checkiner startup [in /home/denis/Dev/checkiner/app/__init__.py:49]
2022-06-07 11:19:39,457 ERROR: Exception on /reset_password_request [POST] [in /home/denis/Dev/checkiner/.venv/lib/python3.8/site-packages/flask/app.py:1455]
Traceback (most recent call last):
  File "/home/denis/Dev/checkiner/.venv/lib/python3.8/site-packages/flask/app.py", line 2077, in wsgi_app
    response = self.full_dispatch_request()
  File "/home/denis/Dev/checkiner/.venv/lib/python3.8/site-packages/flask/app.py", line 1525, in full_dispatch_request
    rv = self.handle_user_exception(e)
  File "/home/denis/Dev/checkiner/.venv/lib/python3.8/site-packages/flask/app.py", line 1523, in full_dispatch_request
    rv = self.dispatch_request()
  File "/home/denis/Dev/checkiner/.venv/lib/python3.8/site-packages/flask/app.py", line 1509, in dispatch_request
    return self.ensure_sync(self.view_functions[rule.endpoint])(**req.view_args)
  File "/home/denis/Dev/checkiner/app/routes.py", line 168, in reset_password_request
    send_password_reset_email(user)
  File "/home/denis/Dev/checkiner/app/email.py", line 19, in send_password_reset_email
    text_body=render_template('email/reset_password.txt',
  File "/home/denis/Dev/checkiner/.venv/lib/python3.8/site-packages/flask/templating.py", line 149, in render_template
    ctx.app.jinja_env.get_or_select_template(template_name_or_list),
  File "/home/denis/Dev/checkiner/.venv/lib/python3.8/site-packages/jinja2/environment.py", line 1071, in get_or_select_template
    return self.get_template(template_name_or_list, parent, globals)
  File "/home/denis/Dev/checkiner/.venv/lib/python3.8/site-packages/jinja2/environment.py", line 1000, in get_template
    return self._load_template(name, globals)
  File "/home/denis/Dev/checkiner/.venv/lib/python3.8/site-packages/jinja2/environment.py", line 959, in _load_template
    template = self.loader.load(self, name, self.make_globals(globals))
  File "/home/denis/Dev/checkiner/.venv/lib/python3.8/site-packages/jinja2/loaders.py", line 126, in load
    source, filename, uptodate = self.get_source(environment, name)
  File "/home/denis/Dev/checkiner/.venv/lib/python3.8/site-packages/flask/templating.py", line 59, in get_source
    return self._get_source_fast(environment, template)
  File "/home/denis/Dev/checkiner/.venv/lib/python3.8/site-packages/flask/templating.py", line 95, in _get_source_fast
    raise TemplateNotFound(template)
jinja2.exceptions.TemplateNotFound: email/reset_password.txt
2022-06-07 11:21:43,842 INFO: Checkiner startup [in /home/denis/Dev/checkiner/app/__init__.py:49]
2022-06-07 11:21:49,876 ERROR: Exception on /reset_password_request [POST] [in /home/denis/Dev/checkiner/.venv/lib/python3.8/site-packages/flask/app.py:1455]
Traceback (most recent call last):
  File "/home/denis/Dev/checkiner/.venv/lib/python3.8/site-packages/flask/app.py", line 2077, in wsgi_app
    response = self.full_dispatch_request()
  File "/home/denis/Dev/checkiner/.venv/lib/python3.8/site-packages/flask/app.py", line 1525, in full_dispatch_request
    rv = self.handle_user_exception(e)
  File "/home/denis/Dev/checkiner/.venv/lib/python3.8/site-packages/flask/app.py", line 1523, in full_dispatch_request
    rv = self.dispatch_request()
  File "/home/denis/Dev/checkiner/.venv/lib/python3.8/site-packages/flask/app.py", line 1509, in dispatch_request
    return self.ensure_sync(self.view_functions[rule.endpoint])(**req.view_args)
  File "/home/denis/Dev/checkiner/app/routes.py", line 168, in reset_password_request
    send_password_reset_email(user)
  File "/home/denis/Dev/checkiner/app/email.py", line 19, in send_password_reset_email
    text_body=render_template('reset_password.txt',
  File "/home/denis/Dev/checkiner/.venv/lib/python3.8/site-packages/flask/templating.py", line 149, in render_template
    ctx.app.jinja_env.get_or_select_template(template_name_or_list),
  File "/home/denis/Dev/checkiner/.venv/lib/python3.8/site-packages/jinja2/environment.py", line 1071, in get_or_select_template
    return self.get_template(template_name_or_list, parent, globals)
  File "/home/denis/Dev/checkiner/.venv/lib/python3.8/site-packages/jinja2/environment.py", line 1000, in get_template
    return self._load_template(name, globals)
  File "/home/denis/Dev/checkiner/.venv/lib/python3.8/site-packages/jinja2/environment.py", line 959, in _load_template
    template = self.loader.load(self, name, self.make_globals(globals))
  File "/home/denis/Dev/checkiner/.venv/lib/python3.8/site-packages/jinja2/loaders.py", line 126, in load
    source, filename, uptodate = self.get_source(environment, name)
  File "/home/denis/Dev/checkiner/.venv/lib/python3.8/site-packages/flask/templating.py", line 59, in get_source
    return self._get_source_fast(environment, template)
  File "/home/denis/Dev/checkiner/.venv/lib/python3.8/site-packages/flask/templating.py", line 95, in _get_source_fast
    raise TemplateNotFound(template)
jinja2.exceptions.TemplateNotFound: reset_password.txt
2022-06-07 11:22:38,183 INFO: Checkiner startup [in /home/denis/Dev/checkiner/app/__init__.py:49]
2022-06-07 11:22:40,476 ERROR: Exception on /index [GET] [in /home/denis/Dev/checkiner/.venv/lib/python3.8/site-packages/flask/app.py:1455]
Traceback (most recent call last):
  File "/home/denis/Dev/checkiner/.venv/lib/python3.8/site-packages/flask/app.py", line 2077, in wsgi_app
    response = self.full_dispatch_request()
  File "/home/denis/Dev/checkiner/.venv/lib/python3.8/site-packages/flask/app.py", line 1525, in full_dispatch_request
    rv = self.handle_user_exception(e)
  File "/home/denis/Dev/checkiner/.venv/lib/python3.8/site-packages/flask/app.py", line 1523, in full_dispatch_request
    rv = self.dispatch_request()
  File "/home/denis/Dev/checkiner/.venv/lib/python3.8/site-packages/flask/app.py", line 1509, in dispatch_request
    return self.ensure_sync(self.view_functions[rule.endpoint])(**req.view_args)
  File "/home/denis/Dev/checkiner/app/routes.py", line 25, in index
    posts = current_user.followed_posts().paginate(
AttributeError: 'AnonymousUserMixin' object has no attribute 'followed_posts'
